<?xml version="1.0"?>
<robot name="sample1">
  <gazebo>
    <plugin name="gazebo_ros_control" filename="libgazebo_ros_control.so">
      <robotNamespace>/sample1</robotNamespace>
    </plugin>
    <static>false</static>
  </gazebo>
  <link name="base_link">
    <visual name="visual">
      <origin xyz="0 0 0.01" rpy="0 0 0"/>
      <geometry>
	<box size="0.1 0.05 0.02"/>
      </geometry>
    </visual>
    <collision name="collision">
      <origin xyz="0 0 0.01" rpy="0 0 0"/>
      <geometry>
	<box size="0.1 0.05 0.02"/>
      </geometry>
    </collision>
    <inertial>
      <origin xyz="0 0 0.01" rpy="0 0 0"/>
      <mass value="0.1"/>
      <inertia ixx="0.000025" iyy="0.00009" izz="0.000105" ixy="0" iyz="0" ixz="0"/>
    </inertial>
  </link>
  <gazebo reference="base_link">
      <selfCollide>true</selfCollide>
  </gazebo>

  
  <joint name="ld_hinge" type="revolute">
    <origin xyz="-0.045 -0.025 0.015" rpy="0 0 0"/>
    <parent link="base_link"/>
    <child link="left"/>
    <axis xyz="0 1 0"/>
    <limit effort="0.4" velocity="1.5707" lower="-1.5707" upper="1.5707" />
  </joint>

  <link name="left">
    <visual name="visual">
      <origin xyz="0 -0.005 0.045" rpy="0 0 0"/>
      <geometry>
	<box size="0.01 0.01 0.1"/>
      </geometry>
    </visual>
    <collision name="collision">
      <origin xyz="0 -0.005 0.045" rpy="0 0 0"/>
      <geometry>
	<box size="0.01 0.01 0.1"/>
      </geometry>
    </collision>
    <inertial>
      <origin xyz="0 -0.005 0.045" rpy="0 0 0"/>
      <mass value="0.01"/>
      <inertia ixx="0.0000085" iyy="0.0000085" izz="0.0000002"  ixy="0" iyz="0" ixz="0"/>
    </inertial>
  </link>
  <gazebo reference="left">
      <selfCollide>true</selfCollide>
  </gazebo>

  <joint name="lu_hinge" type="revolute">
    <origin xyz="0 0 0.09" rpy="0 0 0"/>
    <parent link="left"/>
    <child link="top"/>
    <axis xyz="0 1 0"/>
    <limit effort="0" velocity="1.5707" lower="-1.5707" upper="1.5707" />
  </joint>

  <link name="top">
    <visual name="visual">
      <origin xyz="0.045 0.005 0" rpy="0 0 0"/>
      <geometry>
	<box size="0.1 0.01 0.01"/>
      </geometry>
    </visual>
    <collision name="collision">
      <origin xyz="0.045 0.005 0" rpy="0 0 0"/>
      <geometry>
	<box size="0.1 0.01 0.01"/>
      </geometry>
    </collision>
    <inertial>
      <origin xyz="0.045 0.005 0" rpy="0 0 0"/>
      <mass value="0.01"/>
      <inertia ixx="0.0000002" iyy="0.0000085" izz="0.0000085" ixy="0" iyz="0" ixz="0"/>
    </inertial>
  </link>
  <gazebo reference="top">
      <selfCollide>true</selfCollide>
  </gazebo>

  <joint name="rd_hinge" type="revolute">
    <origin xyz="0.045 -0.025 0.015" rpy="0 0 0"/>
    <parent link="base_link"/>
    <child link="right"/>
    <axis xyz="0 1 0"/>
    <limit effort="0.0" velocity="1.5707" lower="-1.5707" upper="1.5707" />
  </joint>

  <link name="right">
    <visual name="visual">
      <origin xyz="0 -0.005 0.045" rpy="0 0 0"/>
      <geometry>
	<box size="0.01 0.01 0.1"/>
      </geometry>
    </visual>
    <collision name="collision">
      <origin xyz="0 -0.005 0.045" rpy="0 0 0"/>
      <geometry>
	<box size="0.01 0.01 0.1"/>
      </geometry>
    </collision>
    <inertial>
      <origin xyz="0 -0.005 0.045" rpy="0 0 0"/>
      <mass value="0.01"/>
      <inertia ixx="0.0000085" iyy="0.0000085" izz="0.0000002"  ixy="0" iyz="0" ixz="0"/>
    </inertial>
  </link>
  <gazebo reference="left">
      <selfCollide>true</selfCollide>
  </gazebo>
  
  <transmission name="tran_ld">
      <type>transmission_interface/SimpleTransmission</type>
      <joint name="ld_hinge">
    	<hardwareInterface>hardware_interface/PositionJointInterface</hardwareInterface>
      </joint>
      <actuator name="motor_ld">
    	<hardwareInterface>hardware_interface/PositionJointInterface</hardwareInterface>
    	<mechanicalReduction>1</mechanicalReduction>
      </actuator>
  </transmission>

  <transmission name="tran_lu">
      <type>transmission_interface/SimpleTransmission</type>
      <joint name="lu_hinge">
    	<hardwareInterface>hardware_interface/PositionJointInterface</hardwareInterface>
      </joint>
      <actuator name="motor_lu">
    	<hardwareInterface>hardware_interface/PositionJointInterface</hardwareInterface>
    	<mechanicalReduction>1</mechanicalReduction>
      </actuator>
  </transmission>

  <transmission name="tran_rd">
      <type>transmission_interface/SimpleTransmission</type>
      <joint name="rd_hinge">
    	<hardwareInterface>hardware_interface/PositionJointInterface</hardwareInterface>
      </joint>
      <actuator name="motor_rd">
    	<hardwareInterface>hardware_interface/PositionJointInterface</hardwareInterface>
    	<mechanicalReduction>1</mechanicalReduction>
      </actuator>
  </transmission>
  
  
</robot>
